Workbook

Sheet Summary
B2: ACA – Auto Contract Analyzer · Cost Estimation
B3: Deliverable #4 · Vaibhav Soni, AI PM · V1.0 · 10 Oct 2026 · all assumptions approved by Vaibhav (see Assumptions Log)
B5: Headline (per month unless stated) | C5: Low | D5: Median | E5: High | F5: Note
B6: Contracts + NDAs received | C6: =Inference!C8+Inference!C9 -> 7 | D6: =Inference!D8+Inference!D9 -> 9 | E6: =Inference!E8+Inference!E9 -> 18 | F6: Today 7–9 a month; High = 2x
B7: AI reviews run (incl. re-reviews after negotiation) | C7: =Inference!C12+Inference!C13 -> 7 | D7: =Inference!D12+Inference!D13 -> 13 | E7: =Inference!E12+Inference!E13 -> 44 | F7: 4 AI calls each
B8: Cost of one contract review — Claude Fable 5.1 | C8: =Inference!J14 -> 0.383705 | D8: =Inference!K14 -> 0.817841 | E8: =Inference!L14 -> 1.447841
B9: Cost of one contract review — Claude Opus 5.5 | C9: =Inference!J15 -> 0.153482 | D9: =Inference!K15 -> 0.3271364 | E9: =Inference!L15 -> 0.5791364
B10: Cost of one contract review — Claude Sonnet 5.5 | C10: =Inference!J16 -> 0.076741 | D10: =Inference!K16 -> 0.1635682 | E10: =Inference!L16 -> 0.2895682
B11: Cost of one contract review — Claude Haiku 5.5 | C11: =Inference!J17 -> 0.00383705 | D11: =Inference!K17 -> 0.00817841 | E11: =Inference!L17 -> 0.01447841
B12: AI inference per month — Claude Fable 5.1 | C12: =Inference!J35 -> 2.674327 | D12: =Inference!K35 -> 9.055433 | E12: =Inference!L35 -> 46.837004
B13: AI inference per month — Claude Opus 5.5 | C13: =Inference!J36 -> 1.0697308 | D13: =Inference!K36 -> 3.6221732 | E13: =Inference!L36 -> 18.734802
B14: AI inference per month — Claude Sonnet 5.5 | C14: =Inference!J37 -> 0.5348654 | D14: =Inference!K37 -> 1.8110866 | E14: =Inference!L37 -> 9.3674008
B15: AI inference per month — Claude Haiku 5.5 | C15: =Inference!J38 -> 0.02674327 | D15: =Inference!K38 -> 0.09055433 | E15: =Inference!L38 -> 0.46837004
B16: Embeddings per month | C16: =Embeddings!C21 -> 0.003439488 | D16: =Embeddings!D21 -> 0.022815 | E16: =Embeddings!E21 -> 0.12337 | F16: Rounding error, as in Session 9
B17: Infrastructure per month (production) | C17: =Infrastructure!$D$12 -> 52 | D17: =Infrastructure!$D$12 -> 52 | E17: =Infrastructure!$D$12 -> 52 | F17: Prototype runs on free tiers ($0)
B18: ACA running cost per month (model in Cost Savings!C4) | C18: ='Cost Savings'!C28 -> 52.538305 | D18: ='Cost Savings'!D28 -> 53.833902 | E18: ='Cost Savings'!E28 -> 61.490771
B19: One-time setup: register build + indexing (selected model) | C19: =INDEX(Inference!$J$43:$L$46,MATCH('Cost Savings'!$C$4,Inference!$I$43:$I$46,0),1)+Embeddings!C15 -> 0.23140198 | D19: =INDEX(Inference!$J$43:$L$46,MATCH('Cost Savings'!$C$4,Inference!$I$43:$I$46,0),2)+Embeddings!D15 -> 0.41563525 | E19: =INDEX(Inference!$J$43:$L$46,MATCH('Cost Savings'!$C$4,Inference!$I$43:$I$46,0),3)+Embeddings!E15 -> 0.73207608 | F19: 17 signed contracts
B20: KD hours saved per month (North Star) | C20: ='Cost Savings'!C32 -> 10 | D20: ='Cost Savings'!D32 -> 15 | E20: ='Cost Savings'!E32 -> 34 | F20: PRD target ≥ 10
B21: Cost today (KD time + counsel) | C21: ='Cost Savings'!C17 -> 1266.6667 | D21: ='Cost Savings'!D17 -> 1616.6667 | E21: ='Cost Savings'!E17 -> 3433.3333 | F21: KD hour valued at $50
B22: Cost with ACA (KD time + counsel + ACA) | C22: ='Cost Savings'!C29 -> 819.20497 | D22: ='Cost Savings'!D29 -> 920.50057 | E22: ='Cost Savings'!E29 -> 1378.1574
B23: Savings per month | C23: ='Cost Savings'!C33 -> 447.4617 | D23: ='Cost Savings'!D33 -> 696.1661 | E23: ='Cost Savings'!E33 -> 2055.1759
B24: % savings | C24: ='Cost Savings'!C34 -> 0.35325923 | D24: ='Cost Savings'!D34 -> 0.43061821 | E24: ='Cost Savings'!E34 -> 0.59859492
B26: What the numbers say
B27: • AI cost is tiny next to the value of KD's time: even the top tier (Claude Fable 5.1) in the High case stays under $50 a month; Sonnet 5.5 at Median is ~$1.80, while one saved KD hour is worth $50.
B28: • So cost does not force a cheap model. Pick the tier that passes the §11 evals (conflict recall 100%, clause precision ≥ 80%); a stronger model on the conflict check is affordable.
B29: • The 4-call design (re-sending the contract each call) is affordable; prompt caching of the contract would cut input cost further but is not counted here.
B30: • Contract length drives the bill: a 20k-word MSA review costs ~4x a dataset-length draft (Sonnet 5.5: $0.29 vs $0.08). Even the largest call (~31K input tokens) stays far below the 272K long-context threshold.
B31: • Fixed infrastructure (~$52/month in production) is larger than the AI cost at today's volume; the prototype runs on free tiers.
B32: • The business case rests on KD's hours (North Star), not on token cost: ~10–34 hours a month saved, ~35–60% of today's cost.
B34: Legend
B35: Blue = input you can change
B36: Black = formula
B37: Green = linked from another tab
B38: Method: Session 9 master sheet (Inference → Embeddings → Cost Savings), with Low / Median / High per assumption.

Sheet Inference
B2: Inference — LLM token cost of one ACA contract review (Session 9 method)
B3: Low / Median / High per assumption (Session 9: 'build a low, median and high estimate'). A 'query' here = one AI call. One contract review = 4 AI calls (PRD §9.3 steps 6–9), so it gets its own table; obligation extraction after signing is a different prompt shape, so it gets another.
I4: Model Selection + Cost Estimation
B5: Description | C5: Low | D5: Median | E5: High | F5: Where the number came from | G5: Status | I5: Model Name | J5: Input cost($) per 1M token | K5: Output cost($) per 1M token
B6: Volume (per month) | I6: Claude Fable 5.1 | J6: 10 | K6: 50
B7: Tokens per word | C7: 1.3 | D7: 1.3 | E7: 1.3 | F7: Session 9 rule of thumb (1.2–1.3x word count) | G7: Session 9 | I7: Claude Opus 5.5 | J7: 4 | K7: 20
B8: Contracts received (MSA / SOW / BAA / partner) | C8: 3 | D8: 4 | E8: 8 | F8: Vaibhav 7 Oct: 3–4 contracts a month. High = 2x volume (PRD §8 scalability) | G8: Vaibhav 7 Oct / PRD §8 | I8: Claude Sonnet 5.5 | J8: 2 | K8: 10
B9: NDAs received | C9: 4 | D9: 5 | E9: 10 | F9: Vaibhav 7 Oct: 4–5 NDAs a month. High = 2x volume (PRD §8) | G9: Vaibhav 7 Oct / PRD §8 | I9: Claude Haiku 5.5 | J9: 0.1 | K9: 0.5
B10: Review rounds per contract (re-upload after each negotiation round) | C10: 1 | D10: 2 | E10: 3 | F10: Vaibhav 10 Oct approved ~2 rounds (Median). Low 1 / High 3 proposed by Claude | G10: Vaibhav 10 Oct | I10: Claude API standard prices, platform.claude.com/docs pricing page, checked 10 Oct 2026. Haiku 5.5 price rises above 100K input tokens per call (largest ACA call ~31K).
B11: Review rounds per NDA | C11: 1 | D11: 1 | E11: 2 | F11: NDAs are usually short and rarely renegotiated; High allows one redraft | G11: Vaibhav 10 Oct
B12: Contract reviews per month | C12: =C8*C10 -> 3 | D12: =D8*D10 -> 8 | E12: =E8*E10 -> 24 | F12: Formula: contracts received x review rounds | I12: Cost per contract review ($)
B13: NDA reviews per month | C13: =C9*C11 -> 4 | D13: =D9*D11 -> 5 | E13: =E9*E11 -> 20 | F13: Formula: NDAs received x review rounds | I13: Model Name | J13: Low | K13: Median | L13: High
B14: Contracts + NDAs signed per month (obligation extraction) | C14: =C8+C9 -> 7 | D14: =D8+D9 -> 9 | E14: =E8+E9 -> 18 | F14: Assumes every contract and NDA received is eventually signed (upper bound) | I14: =$I$6 -> Claude Fable 5.1 | J14: =$J$6*C$36/1000000+$K$6*C$42/1000000 -> 0.383705 | K14: =$J$6*D$36/1000000+$K$6*D$42/1000000 -> 0.817841 | L14: =$J$6*E$36/1000000+$K$6*E$42/1000000 -> 1.447841
I15: =$I$7 -> Claude Opus 5.5 | J15: =$J$7*C$36/1000000+$K$7*C$42/1000000 -> 0.153482 | K15: =$J$7*D$36/1000000+$K$7*D$42/1000000 -> 0.3271364 | L15: =$J$7*E$36/1000000+$K$7*E$42/1000000 -> 0.5791364
B16: Table A — Contract review: 4 AI calls per review (input tokens) | I16: =$I$8 -> Claude Sonnet 5.5 | J16: =$J$8*C$36/1000000+$K$8*C$42/1000000 -> 0.076741 | K16: =$J$8*D$36/1000000+$K$8*D$42/1000000 -> 0.1635682 | L16: =$J$8*E$36/1000000+$K$8*E$42/1000000 -> 0.2895682
B17: Words per contract | C17: 2132 | D17: 10000 | E17: 20000 | F17: Low = average of the 10 in-scope incoming drafts in the dataset (largest: Harrington MSA 3,416). Median/High = real client-paper MSAs ~10–20k words (PRD §8) | G17: Dataset / PRD §8 | I17: =$I$9 -> Claude Haiku 5.5 | J17: =$J$9*C$36/1000000+$K$9*C$42/1000000 -> 0.00383705 | K17: =$J$9*D$36/1000000+$K$9*D$42/1000000 -> 0.00817841 | L17: =$J$9*E$36/1000000+$K$9*E$42/1000000 -> 0.01447841
B18: Contract tokens (masked text) | C18: =C17*C7 -> 2771.6 | D18: =D17*D7 -> 13000 | E18: =E17*E7 -> 26000 | F18: Formula: words x tokens per word
B19: AI calls per review | C19: 4 | D19: 4 | E19: 4 | F19: Call 1 read every clause + key terms · Call 2 vs KD's positions & incidents · Call 3 vs commitments register · Call 4 fairness / mutuality (PRD §9.3 steps 6–9). Each call re-sends the contract | G19: Vaibhav 10 Oct | I19: Cost per NDA review ($)
B20: System prompt per call (tokens) | C20: 800 | D20: 800 | E20: 800 | F20: Session 9 chatbot prompt = 250. ACA prompts also carry guardrails, 'no source, no flag' citation rules and the output format | G20: Vaibhav 10 Oct | I20: Model Name | J20: Low | K20: Median | L20: High
B21: Deal metadata per call (tokens) | C21: 100 | D21: 100 | E21: 100 | F21: Type, counterparty, entity, value, deadline, POC (PRD §7.1) | G21: Vaibhav 10 Oct | I21: =$I$6 -> Claude Fable 5.1 | J21: =$J$6*C$52/1000000+$K$6*C$53/1000000 -> 0.261981 | K21: =$J$6*D$52/1000000+$K$6*D$53/1000000 -> 0.290841 | L21: =$J$6*E$52/1000000+$K$6*E$53/1000000 -> 0.418841
B22: Call 2 — KD's positions: checklist + negotiation notes (words, sent in full) | C22: 1469 | D22: 1469 | E22: 1469 | F22: Dataset: karandeep_contract_checklist.md 377 + negotiation_notes.md 1,092 words | G22: Dataset | I22: =$I$7 -> Claude Opus 5.5 | J22: =$J$7*C$52/1000000+$K$7*C$53/1000000 -> 0.1047924 | K22: =$J$7*D$52/1000000+$K$7*D$53/1000000 -> 0.1163364 | L22: =$J$7*E$52/1000000+$K$7*E$53/1000000 -> 0.1675364
B23: Call 2 — past-incident chunk size (tokens) | C23: 300 | D23: 300 | E23: 300 | F23: Meeting notes / post-mortems are short (207–332 words each) | G23: Vaibhav 10 Oct | I23: =$I$8 -> Claude Sonnet 5.5 | J23: =$J$8*C$52/1000000+$K$8*C$53/1000000 -> 0.0523962 | K23: =$J$8*D$52/1000000+$K$8*D$53/1000000 -> 0.0581682 | L23: =$J$8*E$52/1000000+$K$8*E$53/1000000 -> 0.0837682
B24: Call 2 — past-incident top_k | C24: 3 | D24: 3 | E24: 3 | F24: Session 9 top_k = 3 | G24: Session 9 | I24: =$I$9 -> Claude Haiku 5.5 | J24: =$J$9*C$52/1000000+$K$9*C$53/1000000 -> 0.00261981 | K24: =$J$9*D$52/1000000+$K$9*D$53/1000000 -> 0.00290841 | L24: =$J$9*E$52/1000000+$K$9*E$53/1000000 -> 0.00418841
B25: Call 3 — commitments-register entry size (tokens) | C25: 150 | D25: 150 | E25: 150 | F25: One obligation + clause citation + term (PRD FR-5) | G25: Vaibhav 10 Oct
B26: Call 3 — register entries retrieved (top_k) | C26: 10 | D26: 10 | E26: 10 | F26: Higher than 3 because conflicts are tuned for recall (PRD §5: never miss one) | G26: Vaibhav 10 Oct | I26: Cost per obligation extraction ($)
B27: Call 3 — signed-contract clause chunk size (tokens) | C27: 600 | D27: 600 | E27: 600 | F27: Session 9 chunk size 600 (full source clause for citation check) | G27: Session 9 | I27: Model Name | J27: Low | K27: Median | L27: High
B28: Call 3 — signed-contract clauses retrieved (top_k) | C28: 5 | D28: 5 | E28: 5 | F28: Up to 5 source clauses so both sides of a collision can be quoted | G28: Vaibhav 10 Oct | I28: =$I$6 -> Claude Fable 5.1 | J28: =$J$6*C$59/1000000+$K$6*C$60/1000000 -> 0.067898286 | K28: =$J$6*D$59/1000000+$K$6*D$60/1000000 -> 0.11761111 | L28: =$J$6*E$59/1000000+$K$6*E$60/1000000 -> 0.20622222
B29: Call 4 — AtliQ entity facts (words) | C29: 288 | D29: 288 | E29: 288 | F29: Dataset: atliq_entities.md | G29: Dataset | I29: =$I$7 -> Claude Opus 5.5 | J29: =$J$7*C$59/1000000+$K$7*C$60/1000000 -> 0.027159314 | K29: =$J$7*D$59/1000000+$K$7*D$60/1000000 -> 0.047044444 | L29: =$J$7*E$59/1000000+$K$7*E$60/1000000 -> 0.082488889
B30: Call 4 — regulation & deal-bundle list (tokens) | C30: 1000 | D30: 1000 | E30: 1000 | F30: Fixed curated list, 8 countries x sector (PRD FR-8); not yet written | G30: Vaibhav 10 Oct | I30: =$I$8 -> Claude Sonnet 5.5 | J30: =$J$8*C$59/1000000+$K$8*C$60/1000000 -> 0.013579657 | K30: =$J$8*D$59/1000000+$K$8*D$60/1000000 -> 0.023522222 | L30: =$J$8*E$59/1000000+$K$8*E$60/1000000 -> 0.041244444
B31: Contract text across all calls | C31: =C18*C19 -> 11086.4 | D31: =D18*D19 -> 52000 | E31: =E18*E19 -> 104000 | F31: Formula: contract tokens x AI calls | I31: =$I$9 -> Claude Haiku 5.5 | J31: =$J$9*C$59/1000000+$K$9*C$60/1000000 -> 0.00067898286 | K31: =$J$9*D$59/1000000+$K$9*D$60/1000000 -> 0.0011761111 | L31: =$J$9*E$59/1000000+$K$9*E$60/1000000 -> 0.0020622222
B32: System prompt + metadata across all calls | C32: =(C20+C21)*C19 -> 3600 | D32: =(D20+D21)*D19 -> 3600 | E32: =(E20+E21)*E19 -> 3600 | F32: Formula: (system prompt + metadata) x AI calls
B33: Call 2 retrieved context | C33: =C22*C7+C23*C24 -> 2809.7 | D33: =D22*D7+D23*D24 -> 2809.7 | E33: =E22*E7+E23*E24 -> 2809.7 | F33: Formula: KD positions tokens + incident chunk x top_k | I33: Total inference cost per month ($)
B34: Call 3 retrieved context | C34: =C25*C26+C27*C28 -> 4500 | D34: =D25*D26+D27*D28 -> 4500 | E34: =E25*E26+E27*E28 -> 4500 | F34: Formula: register entry x top_k + clause chunk x top_k | I34: Model Name | J34: Low | K34: Median | L34: High
B35: Call 4 retrieved context | C35: =C29*C7+C30 -> 1374.4 | D35: =D29*D7+D30 -> 1374.4 | E35: =E29*E7+E30 -> 1374.4 | F35: Formula: entity facts tokens + regulation list | I35: =$I$6 -> Claude Fable 5.1 | J35: =J14*C$12+J21*C$13+J28*C$14 -> 2.674327 | K35: =K14*D$12+K21*D$13+K28*D$14 -> 9.055433 | L35: =L14*E$12+L21*E$13+L28*E$14 -> 46.837004
B36: Total input tokens per contract review | C36: =C31+C32+C33+C34+C35 -> 23370.5 | D36: =D31+D32+D33+D34+D35 -> 64284.1 | E36: =E31+E32+E33+E34+E35 -> 116284.1 | F36: Sum of the five lines above | I36: =$I$7 -> Claude Opus 5.5 | J36: =J15*C$12+J22*C$13+J29*C$14 -> 1.0697308 | K36: =K15*D$12+K22*D$13+K29*D$14 -> 3.6221732 | L36: =L15*E$12+L22*E$13+L29*E$14 -> 18.734802
B37: Table A — output tokens | I37: =$I$8 -> Claude Sonnet 5.5 | J37: =J16*C$12+J23*C$13+J30*C$14 -> 0.5348654 | K37: =K16*D$12+K23*D$13+K30*D$14 -> 1.8110866 | L37: =L16*E$12+L23*E$13+L30*E$14 -> 9.3674008
B38: Call 1 — clause-by-clause key terms | C38: 1000 | D38: 1500 | E38: 2500 | F38: Structured list of clauses and key terms; grows with contract length | G38: Vaibhav 10 Oct | I38: =$I$9 -> Claude Haiku 5.5 | J38: =J17*C$12+J24*C$13+J31*C$14 -> 0.02674327 | K38: =K17*D$12+K24*D$13+K31*D$14 -> 0.09055433 | L38: =L17*E$12+L24*E$13+L31*E$14 -> 0.46837004
B39: Call 2 — flags vs KD's positions | C39: 800 | D39: 800 | E39: 1200 | F39: Each flag: quote, source, KD's past position, 'Suggestion – KD decides' | G39: Vaibhav 10 Oct | I39: Formula: review cost x reviews + NDA cost x NDA reviews + extraction cost x documents signed
B40: Call 3 — conflicts with existing commitments | C40: 600 | D40: 600 | E40: 1000 | F40: Both clauses quoted per conflict | G40: Vaibhav 10 Oct
B41: Call 4 — fairness / mutuality flags | C41: 600 | D41: 600 | E41: 1000 | F41: Mutuality test results + proportionality flag | G41: Vaibhav 10 Oct | I41: One-time register build ($)
...

Sheet Embeddings
B2: Embeddings — indexing the knowledge base + embedding each incoming draft
B4: Description | C4: Low | D4: Median | E4: High | F4: Where the number came from | G4: Status
B5: Tokens per word | C5: =Inference!C7 -> 1.3 | D5: =Inference!D7 -> 1.3 | E5: =Inference!E7 -> 1.3 | F5: Linked to Inference
B6: Embedding cost per 1M tokens ($) | C6: 0.13 | D6: 0.13 | E6: 0.13 | F6: Session 9 price (text-embedding-3-large). Claude has no embedding model; Anthropic points to Voyage AI (voyage-law-2 $0.12/1M, 50M tokens free), so $0.13 is slightly conservative | G6: Session 9
B8: One-time: index the knowledge base (vector DB)
B9: Signed contracts (tokens) | C9: =Inference!C64*Inference!C65*C5 -> 30144.4 | D9: =Inference!D64*Inference!D65*D5 -> 116638.89 | E9: =Inference!E64*Inference!E65*E5 -> 233277.78 | F9: Formula: 17 contracts x avg words x tokens per word (Inference Table D)
B10: KD's checklist + negotiation notes (tokens) | C10: =Inference!C22*C5 -> 1909.7 | D10: =Inference!D22*D5 -> 1909.7 | E10: =Inference!E22*E5 -> 1909.7 | F10: Linked to Inference
B11: Meeting notes / past incidents (words) | C11: 991 | D11: 991 | E11: 991 | F11: Dataset: 4 meeting notes (Brightwater, queue, counsel call, Harrington huddle) | G11: Dataset
B12: Meeting notes / past incidents (tokens) | C12: =C11*C5 -> 1288.3 | D12: =D11*D5 -> 1288.3 | E12: =E11*E5 -> 1288.3 | F12: Formula: words x tokens per word
B13: Entity facts + regulation list (tokens) | C13: =Inference!C29*C5+Inference!C30 -> 1374.4 | D13: =Inference!D29*D5+Inference!D30 -> 1374.4 | E13: =Inference!E29*E5+Inference!E30 -> 1374.4 | F13: Linked to Inference
B14: Total tokens for the knowledge base | C14: =SUM(C9:C10)+C12+C13 -> 34716.8 | D14: =SUM(D9:D10)+D12+D13 -> 121211.29 | E14: =SUM(E9:E10)+E12+E13 -> 237850.18 | F14: Sum
B15: One-time indexing cost ($) | C15: =C14*C6/1000000 -> 0.004513184 | D15: =D14*D6/1000000 -> 0.015757468 | E15: =E14*E6/1000000 -> 0.030920523 | F15: Formula: tokens x cost per 1M / 1,000,000
B17: Recurring per month
B18: Newly signed documents added to the index (tokens) | C18: =Inference!C14*Inference!C58 -> 13228.8 | D18: =Inference!D14*Inference!D58 -> 61750 | E18: =Inference!E14*Inference!E58 -> 247000 | F18: Formula: documents signed x signed-document tokens (Inference Table C)
B19: Incoming drafts embedded to search the register (tokens) | C19: =Inference!C12*Inference!C18+Inference!C13*Inference!C49 -> 13228.8 | D19: =Inference!D12*Inference!D18+Inference!D13*Inference!D49 -> 113750 | E19: =Inference!E12*Inference!E18+Inference!E13*Inference!E49 -> 702000 | F19: ACA's 'user query' = every clause of the draft, so the whole draft is embedded once per review
B20: Total embedding tokens per month | C20: =C18+C19 -> 26457.6 | D20: =D18+D19 -> 175500 | E20: =E18+E19 -> 949000 | F20: Sum
B21: Total embedding cost per month ($) | C21: =C20*C6/1000000 -> 0.003439488 | D21: =D20*D6/1000000 -> 0.022815 | E21: =E20*E6/1000000 -> 0.12337 | F21: Formula: tokens x cost per 1M / 1,000,000

Sheet Infrastructure
B2: Infrastructure — monthly running cost outside the AI tokens
B3: Same across Low / Median / High: 2x today's volume still fits these plans.
B5: Component | C5: Prototype ($/month) | D5: Production ($/month) | E5: What it covers / source | F5: Status
B6: Frontend hosting — Vercel (React) | C6: 0 | D6: 20 | E6: Hobby free tier for the prototype; Pro = $20 per seat per month (list price — verify) | F6: Vaibhav 10 Oct
B7: Database + vector store — Supabase (Postgres + pgvector) | C7: 0 | D7: 25 | E7: Contracts, register, audit log and embeddings in one place; Free tier → Pro $25/month | F7: Vaibhav 10 Oct
B8: Python AI service — Render (masking, OCR, AI calls) | C8: 0 | D8: 7 | E8: Free instance for the prototype; Starter $7/month (always on, needed for 99.9% uptime) | F8: Vaibhav 10 Oct
B9: Email intake address (inbound email parsing) | C9: 0 | D9: 0 | E9: Free tier of an inbound-parse service; ~10–20 emails a month | F9: Vaibhav 10 Oct
B10: OCR for scanned contracts — Tesseract (open source) | C10: 0 | D10: 0 | E10: Runs inside the Python service; no per-page fee | F10: Vaibhav 10 Oct
B11: Masking — pattern rules + open-source entity recognition | C11: 0 | D11: 0 | E11: Runs inside the Python service (PRD FR-4) | F11: Vaibhav 10 Oct
B12: Total infrastructure per month | C12: =SUM(C6:C11) -> 0 | D12: =SUM(D6:D11) -> 52
B14: Not in this model (Session 9 §7 — sits outside the PM's token estimate)
B15: • People: engineering build and maintenance, KD's and POCs' time to confirm register entries
B16: • Outside counsel to review the regulation list before live use (PRD §16)
B17: • Observability / evaluation tooling beyond the built-in audit log
B18: • Re-ranking model (not in the V1 design)
B19: • Data-residency or enterprise API terms if required for real contracts (PRD §16 spike)

Sheet Cost Savings
B2: Cost Savings — KD's review time and counsel spend vs ACA running cost
B4: Model used for the business case | C4: Claude Sonnet 5.5 | F4: Pick from the list. Mid tier, as Session 9 chose for its chatbot; per-call tier confirmed by evals (PRD §5) | G4: Vaibhav 10 Oct
B6: Description | C6: Low | D6: Median | E6: High | F6: Where the number came from | G6: Status
B7: Today, without ACA (per month)
B8: Contracts received | C8: =Inference!C8 -> 3 | D8: =Inference!D8 -> 4 | E8: =Inference!E8 -> 8 | F8: Linked to Inference
B9: KD hours per contract today | C9: 3 | D9: 3.5 | E9: 4 | F9: Vaibhav 7 Oct: 3–4 hours per complex client-paper contract (PRD §2.3) | G9: Vaibhav 7 Oct
B10: NDAs received | C10: =Inference!C9 -> 4 | D10: =Inference!D9 -> 5 | E10: =Inference!E9 -> 10 | F10: Linked to Inference
B11: KD hours per NDA today | C11: 2 | D11: 2 | E11: 2 | F11: Vaibhav 7 Oct: ~2 hours per routine review (PRD §2.3) | G11: Vaibhav 7 Oct
B12: KD review hours per month today | C12: =C8*C9+C10*C11 -> 17 | D12: =D8*D9+D10*D11 -> 24 | E12: =E8*E9+E10*E11 -> 52 | F12: PRD §2.3: ~17–26 hours a month at today's volume
B13: Value of one KD hour ($) | C13: 50 | D13: 50 | E13: 50 | F13: Vaibhav 10 Oct | G13: Vaibhav 10 Oct
B14: KD review cost per month ($) | C14: =C12*C13 -> 850 | D14: =D12*D13 -> 1200 | E14: =E12*E13 -> 2600 | F14: Formula: hours x hourly value
B15: Outside counsel per year without ACA ($) | C15: 5000 | D15: 5000 | E15: 10000 | F15: Vaibhav 7 Oct: ~$5,000/year today. High assumes counsel spend doubles with 2x volume | G15: Vaibhav 7 Oct / 10 Oct
B16: Outside counsel per month ($) | C16: =C15/12 -> 416.66667 | D16: =D15/12 -> 416.66667 | E16: =E15/12 -> 833.33333 | F16: Formula: yearly / 12
B17: Total cost today per month ($) | C17: =C14+C16 -> 1266.6667 | D17: =D14+D16 -> 1616.6667 | E17: =E14+E16 -> 3433.3333 | F17: KD time + counsel
B19: With ACA (per month)
B20: KD hours per contract or NDA with ACA | C20: 1 | D20: 1 | E20: 1 | F20: PRD §12 North Star target: KD time ≤ 1 hour per contract | G20: PRD §12
B21: KD review hours per month with ACA | C21: =(C8+C10)*C20 -> 7 | D21: =(D8+D10)*D20 -> 9 | E21: =(E8+E10)*E20 -> 18 | F21: Formula: (contracts + NDAs) x hours with ACA
B22: KD review cost per month ($) | C22: =C21*C13 -> 350 | D22: =D21*D13 -> 450 | E22: =E21*E13 -> 900 | F22: Formula: hours x hourly value
B23: Outside counsel per year with ACA ($) | C23: 5000 | D23: 5000 | E23: 5000 | F23: PRD §12 target: counsel ≤ ~$5,000/year even as volume grows | G23: PRD §12
B24: Outside counsel per month ($) | C24: =C23/12 -> 416.66667 | D24: =D23/12 -> 416.66667 | E24: =E23/12 -> 416.66667 | F24: Formula: yearly / 12
B25: ACA inference (selected model) ($) | C25: =INDEX(Inference!$J$35:$L$38,MATCH($C$4,Inference!$I$35:$I$38,0),1) -> 0.5348654 | D25: =INDEX(Inference!$J$35:$L$38,MATCH($C$4,Inference!$I$35:$I$38,0),2) -> 1.8110866 | E25: =INDEX(Inference!$J$35:$L$38,MATCH($C$4,Inference!$I$35:$I$38,0),3) -> 9.3674008 | F25: Inference tab, 'Total inference cost per month', row for the model in C4
B26: ACA embeddings ($) | C26: =Embeddings!C21 -> 0.003439488 | D26: =Embeddings!D21 -> 0.022815 | E26: =Embeddings!E21 -> 0.12337 | F26: Embeddings tab, recurring per month
B27: ACA infrastructure, production ($) | C27: =Infrastructure!$D$12 -> 52 | D27: =Infrastructure!$D$12 -> 52 | E27: =Infrastructure!$D$12 -> 52 | F27: Infrastructure tab, production total
B28: ACA running cost per month ($) | C28: =C25+C26+C27 -> 52.538305 | D28: =D25+D26+D27 -> 53.833902 | E28: =E25+E26+E27 -> 61.490771 | F28: Inference + embeddings + infrastructure
B29: Total cost with ACA per month ($) | C29: =C22+C24+C28 -> 819.20497 | D29: =D22+D24+D28 -> 920.50057 | E29: =E22+E24+E28 -> 1378.1574 | F29: KD time + counsel + ACA
B31: Savings
B32: KD hours saved per month (North Star) | C32: =C12-C21 -> 10 | D32: =D12-D21 -> 15 | E32: =E12-E21 -> 34 | F32: PRD §12 target: ≥ 10 hours a month at today's volume
B33: Total savings per month ($) | C33: =C17-C29 -> 447.4617 | D33: =D17-D29 -> 696.1661 | E33: =E17-E29 -> 2055.1759 | F33: Formula: cost today - cost with ACA
B34: % savings | C34: =IFERROR(C33/C17,0) -> 0.35325923 | D34: =IFERROR(D33/D17,0) -> 0.43061821 | E34: =IFERROR(E33/E17,0) -> 0.59859492 | F34: Formula: savings / cost today
B35: Return on ACA running cost (savings ÷ ACA cost) | C35: =IFERROR(C33/C28,0) -> 8.5168659 | D35: =IFERROR(D33/D28,0) -> 12.931741 | E35: =IFERROR(E33/E28,0) -> 33.42251 | F35: How many dollars saved per dollar spent running ACA
B37: Not counted above (memo)
B38: One avoided miss like Brightwater ($, one-off) | C38: 23200 | D38: 23200 | E38: 23200 | F38: PRD §2.3: $9k settlement credit + $14.2k counsel fees, plus ~2 weeks of senior time. Same 19-day delay under Harrington's terms ≈ $80k | G38: PRD §2.3
B39: Months of ACA running cost one avoided miss pays for | C39: =IFERROR(C38/C28,0) -> 441.58258 | D39: =IFERROR(D38/D28,0) -> 430.9552 | E39: =IFERROR(E38/E28,0) -> 377.29239 | F39: Formula: avoided miss / ACA running cost per month

Sheet Assumptions Log
B2: Assumptions log — every typed-in number, where it came from, and whether it is approved
B4: # | C4: Assumption | D4: Low | E4: Median | F4: High | G4: Source | H4: Status
B5: 1 | C5: Tokens per word (Inference) | D5: =Inference!C7 -> 1.3 | E5: =Inference!D7 -> 1.3 | F5: =Inference!E7 -> 1.3 | G5: Session 9 rule of thumb (1.2–1.3x word count) | H5: Session 9
B6: 2 | C6: Contracts received (MSA / SOW / BAA / partner) (Inference) | D6: =Inference!C8 -> 3 | E6: =Inference!D8 -> 4 | F6: =Inference!E8 -> 8 | G6: Vaibhav 7 Oct: 3–4 contracts a month. High = 2x volume (PRD §8 scalability) | H6: Vaibhav 7 Oct / PRD §8
B7: 3 | C7: NDAs received (Inference) | D7: =Inference!C9 -> 4 | E7: =Inference!D9 -> 5 | F7: =Inference!E9 -> 10 | G7: Vaibhav 7 Oct: 4–5 NDAs a month. High = 2x volume (PRD §8) | H7: Vaibhav 7 Oct / PRD §8
B8: 4 | C8: Review rounds per contract (re-upload after each negotiation round) (Inference) | D8: =Inference!C10 -> 1 | E8: =Inference!D10 -> 2 | F8: =Inference!E10 -> 3 | G8: Vaibhav 10 Oct approved ~2 rounds (Median). Low 1 / High 3 proposed by Claude | H8: Vaibhav 10 Oct
B9: 5 | C9: Review rounds per NDA (Inference) | D9: =Inference!C11 -> 1 | E9: =Inference!D11 -> 1 | F9: =Inference!E11 -> 2 | G9: NDAs are usually short and rarely renegotiated; High allows one redraft | H9: Vaibhav 10 Oct
B10: 6 | C10: Words per contract (Inference) | D10: =Inference!C17 -> 2132 | E10: =Inference!D17 -> 10000 | F10: =Inference!E17 -> 20000 | G10: Low = average of the 10 in-scope incoming drafts in the dataset (largest: Harrington MSA 3,416). Median/High = real client-paper MSAs ~10–20k words (PRD §8) | H10: Dataset / PRD §8
B11: 7 | C11: AI calls per review (Inference) | D11: =Inference!C19 -> 4 | E11: =Inference!D19 -> 4 | F11: =Inference!E19 -> 4 | G11: Call 1 read every clause + key terms · Call 2 vs KD's positions & incidents · Call 3 vs commitments register · Call 4 fairness / mutuality (PRD §9.3 steps 6–9). Each call re-sends the contract | H11: Vaibhav 10 Oct
B12: 8 | C12: System prompt per call (tokens) (Inference) | D12: =Inference!C20 -> 800 | E12: =Inference!D20 -> 800 | F12: =Inference!E20 -> 800 | G12: Session 9 chatbot prompt = 250. ACA prompts also carry guardrails, 'no source, no flag' citation rules and the output format | H12: Vaibhav 10 Oct
B13: 9 | C13: Deal metadata per call (tokens) (Inference) | D13: =Inference!C21 -> 100 | E13: =Inference!D21 -> 100 | F13: =Inference!E21 -> 100 | G13: Type, counterparty, entity, value, deadline, POC (PRD §7.1) | H13: Vaibhav 10 Oct
B14: 10 | C14: Call 2 — KD's positions: checklist + negotiation notes (words, sent in full) (Inference) | D14: =Inference!C22 -> 1469 | E14: =Inference!D22 -> 1469 | F14: =Inference!E22 -> 1469 | G14: Dataset: karandeep_contract_checklist.md 377 + negotiation_notes.md 1,092 words | H14: Dataset
B15: 11 | C15: Call 2 — past-incident chunk size (tokens) (Inference) | D15: =Inference!C23 -> 300 | E15: =Inference!D23 -> 300 | F15: =Inference!E23 -> 300 | G15: Meeting notes / post-mortems are short (207–332 words each) | H15: Vaibhav 10 Oct
B16: 12 | C16: Call 2 — past-incident top_k (Inference) | D16: =Inference!C24 -> 3 | E16: =Inference!D24 -> 3 | F16: =Inference!E24 -> 3 | G16: Session 9 top_k = 3 | H16: Session 9
B17: 13 | C17: Call 3 — commitments-register entry size (tokens) (Inference) | D17: =Inference!C25 -> 150 | E17: =Inference!D25 -> 150 | F17: =Inference!E25 -> 150 | G17: One obligation + clause citation + term (PRD FR-5) | H17: Vaibhav 10 Oct
B18: 14 | C18: Call 3 — register entries retrieved (top_k) (Inference) | D18: =Inference!C26 -> 10 | E18: =Inference!D26 -> 10 | F18: =Inference!E26 -> 10 | G18: Higher than 3 because conflicts are tuned for recall (PRD §5: never miss one) | H18: Vaibhav 10 Oct
B19: 15 | C19: Call 3 — signed-contract clause chunk size (tokens) (Inference) | D19: =Inference!C27 -> 600 | E19: =Inference!D27 -> 600 | F19: =Inference!E27 -> 600 | G19: Session 9 chunk size 600 (full source clause for citation check) | H19: Session 9
B20: 16 | C20: Call 3 — signed-contract clauses retrieved (top_k) (Inference) | D20: =Inference!C28 -> 5 | E20: =Inference!D28 -> 5 | F20: =Inference!E28 -> 5 | G20: Up to 5 source clauses so both sides of a collision can be quoted | H20: Vaibhav 10 Oct
B21: 17 | C21: Call 4 — AtliQ entity facts (words) (Inference) | D21: =Inference!C29 -> 288 | E21: =Inference!D29 -> 288 | F21: =Inference!E29 -> 288 | G21: Dataset: atliq_entities.md | H21: Dataset
B22: 18 | C22: Call 4 — regulation & deal-bundle list (tokens) (Inference) | D22: =Inference!C30 -> 1000 | E22: =Inference!D30 -> 1000 | F22: =Inference!E30 -> 1000 | G22: Fixed curated list, 8 countries x sector (PRD FR-8); not yet written | H22: Vaibhav 10 Oct
B23: 19 | C23: Call 1 — clause-by-clause key terms (Inference) | D23: =Inference!C38 -> 1000 | E23: =Inference!D38 -> 1500 | F23: =Inference!E38 -> 2500 | G23: Structured list of clauses and key terms; grows with contract length | H23: Vaibhav 10 Oct
B24: 20 | C24: Call 2 — flags vs KD's positions (Inference) | D24: =Inference!C39 -> 800 | E24: =Inference!D39 -> 800 | F24: =Inference!E39 -> 1200 | G24: Each flag: quote, source, KD's past position, 'Suggestion – KD decides' | H24: Vaibhav 10 Oct
B25: 21 | C25: Call 3 — conflicts with existing commitments (Inference) | D25: =Inference!C40 -> 600 | E25: =Inference!D40 -> 600 | F25: =Inference!E40 -> 1000 | G25: Both clauses quoted per conflict | H25: Vaibhav 10 Oct
B26: 22 | C26: Call 4 — fairness / mutuality flags (Inference) | D26: =Inference!C41 -> 600 | E26: =Inference!D41 -> 600 | F26: =Inference!E41 -> 1000 | G26: Mutuality test results + proportionality flag | H26: Vaibhav 10 Oct
B27: 23 | C27: Words per NDA (Inference) | D27: =Inference!C48 -> 945 | E27: =Inference!D48 -> 1500 | F27: =Inference!E48 -> 3000 | G27: Low = average of the 2 in-scope NDA drafts (FinServe 1,146, LoopMart 743). Median/High allow longer real NDAs | H27: Dataset / Vaibhav 10 Oct
B28: 24 | C28: Total output tokens per NDA review (4 calls) (Inference) | D28: =Inference!C53 -> 1800 | E28: =Inference!D53 -> 1800 | F28: =Inference!E53 -> 2800 | G28: Fewer clauses than an MSA: ~600 key terms + ~400 per check call | H28: Vaibhav 10 Oct
B29: 25 | C29: Output tokens per extraction (obligations list for KD to confirm) (Inference) | D29: =Inference!C60 -> 800 | E29: =Inference!D60 -> 800 | F29: =Inference!E60 -> 1200 | G29: Non-compete, exclusivity, MFN, IP, no-hire, term, Affiliates — each with citation | H29: Vaibhav 10 Oct
B30: 26 | C30: Signed contracts to load (Inference) | D30: =Inference!C64 -> 17 | E30: =Inference!D64 -> 17 | F30: =Inference!E64 -> 17 | G30: Dataset: 17 signed contracts across 6 locations | H30: Dataset
B31: 27 | C31: Average words per signed contract (Inference) | D31: =Inference!C65 -> 1364 | E31: =Inference!D65 -> 5277.7778 | F31: =Inference!E65 -> 10555.556 | G31: Low = dataset (23,180 words / 17). Median/High = Table C average (real contracts are longer) | H31: Dataset
B32: 28 | C32: Embedding cost per 1M tokens ($) (Embeddings) | D32: =Embeddings!C6 -> 0.13 | E32: =Embeddings!D6 -> 0.13 | F32: =Embeddings!E6 -> 0.13 | G32: Session 9 price (text-embedding-3-large). Claude has no embedding model; Anthropic points to Voyage AI (voyage-law-2 $0.12/1M, 50M tokens free), so $0.13 is slightly conservative | H32: Session 9
B33: 29 | C33: Meeting notes / past incidents (words) (Embeddings) | D33: =Embeddings!C11 -> 991 | E33: =Embeddings!D11 -> 991 | F33: =Embeddings!E11 -> 991 | G33: Dataset: 4 meeting notes (Brightwater, queue, counsel call, Harrington huddle) | H33: Dataset
B34: 30 | C34: Frontend hosting — Vercel (React) (Infrastructure) | D34: =Infrastructure!C6 -> 0 | E34: =Infrastructure!D6 -> 20 | G34: Hobby free tier for the prototype; Pro = $20 per seat per month (list price — verify) | H34: Vaibhav 10 Oct
B35: 31 | C35: Database + vector store — Supabase (Postgres + pgvector) (Infrastructure) | D35: =Infrastructure!C7 -> 0 | E35: =Infrastructure!D7 -> 25 | G35: Contracts, register, audit log and embeddings in one place; Free tier → Pro $25/month | H35: Vaibhav 10 Oct
B36: 32 | C36: Python AI service — Render (masking, OCR, AI calls) (Infrastructure) | D36: =Infrastructure!C8 -> 0 | E36: =Infrastructure!D8 -> 7 | G36: Free instance for the prototype; Starter $7/month (always on, needed for 99.9% uptime) | H36: Vaibhav 10 Oct
B37: 33 | C37: Email intake address (inbound email parsing) (Infrastructure) | D37: =Infrastructure!C9 -> 0 | E37: =Infrastructure!D9 -> 0 | G37: Free tier of an inbound-parse service; ~10–20 emails a month | H37: Vaibhav 10 Oct
B38: 34 | C38: OCR for scanned contracts — Tesseract (open source) (Infrastructure) | D38: =Infrastructure!C10 -> 0 | E38: =Infrastructure!D10 -> 0 | G38: Runs inside the Python service; no per-page fee | H38: Vaibhav 10 Oct
B39: 35 | C39: Masking — pattern rules + open-source entity recognition (Infrastructure) | D39: =Infrastructure!C11 -> 0 | E39: =Infrastructure!D11 -> 0 | G39: Runs inside the Python service (PRD FR-4) | H39: Vaibhav 10 Oct
B40: 36 | C40: Model used for the business case (Cost Savings) | E40: ='Cost Savings'!C4 -> Claude Sonnet 5.5 | G40: Mid tier, as Session 9 chose; per-call tier confirmed by evals (PRD §5) | H40: Vaibhav 10 Oct
B41: 37 | C41: KD hours per contract today (Cost Savings) | D41: ='Cost Savings'!C9 -> 3 | E41: ='Cost Savings'!D9 -> 3.5 | F41: ='Cost Savings'!E9 -> 4 | G41: Vaibhav 7 Oct: 3–4 hours per complex client-paper contract (PRD §2.3) | H41: Vaibhav 7 Oct
B42: 38 | C42: KD hours per NDA today (Cost Savings) | D42: ='Cost Savings'!C11 -> 2 | E42: ='Cost Savings'!D11 -> 2 | F42: ='Cost Savings'!E11 -> 2 | G42: Vaibhav 7 Oct: ~2 hours per routine review (PRD §2.3) | H42: Vaibhav 7 Oct
...
